{
    "registryname": "melting_furnace",
    "localizedname": "Melting Furnace",
    "parts": [
        {
            "x": -1,
            "y": 0,
            "z": 0,
            "elements": [
                "gregtechmod:block_advanced_machine_casing@0"
            ]
        },
        {
            "x": -1,
            "y": 0,
            "z": 1,
            "nbt": {"busSize":"6","casingColor":"16777215","id":"minecraft:tileiteminputbus","inventory":{"inventoryArray":[{"holderEmpty":"1b","holderId":"0"},{"holderEmpty":"1b","holderId":"1"},{"holderEmpty":"1b","holderId":"2"},{"holderEmpty":"1b","holderId":"3"},{"holderEmpty":"1b","holderId":"4"},{"holderEmpty":"1b","holderId":"5"},{"holderEmpty":"1b","holderId":"6"},{"holderEmpty":"1b","holderId":"7"},{"holderEmpty":"1b","holderId":"8"},{"holderEmpty":"1b","holderId":"9"},{"holderEmpty":"1b","holderId":"10"},{"holderEmpty":"1b","holderId":"11"},{"holderEmpty":"1b","holderId":"12"},{"holderEmpty":"1b","holderId":"13"},{"holderEmpty":"1b","holderId":"14"},{"holderEmpty":"1b","holderId":"15"},{"holderEmpty":"1b","holderId":"16"},{"holderEmpty":"1b","holderId":"17"},{"holderEmpty":"1b","holderId":"18"},{"holderEmpty":"1b","holderId":"19"},{"holderEmpty":"1b","holderId":"20"},{"holderEmpty":"1b","holderId":"21"},{"holderEmpty":"1b","holderId":"22"},{"holderEmpty":"1b","holderId":"23"},{"holderEmpty":"1b","holderId":"24"},{"holderEmpty":"1b","holderId":"25"},{"holderEmpty":"1b","holderId":"26"},{"holderEmpty":"1b","holderId":"27"},{"holderEmpty":"1b","holderId":"28"},{"holderEmpty":"1b","holderId":"29"},{"holderEmpty":"1b","holderId":"30"},{"holderEmpty":"1b","holderId":"31"}],"outSlots":,"miscSlots":,"inSlots":,"sides":}},
            "elements": [
                "modularmachinery:blockinputbus@6"
            ]
        },
        {
            "x": 0,
            "y": 2,
            "z": 2,
            "elements": [
                "gregtechmod:block_advanced_machine_casing@0"
            ]
        },
        {
            "x": 1,
            "y": 2,
            "z": 1,
            "elements": [
                "gregtechmod:block_advanced_machine_casing@0"
            ]
        },
        {
            "x": 1,
            "y": 0,
            "z": 0,
            "elements": [
                "gregtechmod:block_advanced_machine_casing@0"
            ]
        },
        {
            "x": -1,
            "y": 0,
            "z": 2,
            "elements": [
                "gregtechmod:block_advanced_machine_casing@0"
            ]
        },
        {
            "x": 1,
            "y": 2,
            "z": 2,
            "elements": [
                "gregtechmod:block_advanced_machine_casing@0"
            ]
        },
        {
            "x": 1,
            "y": 0,
            "z": 1,
            "nbt": {"busSize":"6","casingColor":"16777215","id":"minecraft:tileitemoutputbus","inventory":{"inventoryArray":[{"holderEmpty":"1b","holderId":"0"},{"holderEmpty":"1b","holderId":"1"},{"holderEmpty":"1b","holderId":"2"},{"holderEmpty":"1b","holderId":"3"},{"holderEmpty":"1b","holderId":"4"},{"holderEmpty":"1b","holderId":"5"},{"holderEmpty":"1b","holderId":"6"},{"holderEmpty":"1b","holderId":"7"},{"holderEmpty":"1b","holderId":"8"},{"holderEmpty":"1b","holderId":"9"},{"holderEmpty":"1b","holderId":"10"},{"holderEmpty":"1b","holderId":"11"},{"holderEmpty":"1b","holderId":"12"},{"holderEmpty":"1b","holderId":"13"},{"holderEmpty":"1b","holderId":"14"},{"holderEmpty":"1b","holderId":"15"},{"holderEmpty":"1b","holderId":"16"},{"holderEmpty":"1b","holderId":"17"},{"holderEmpty":"1b","holderId":"18"},{"holderEmpty":"1b","holderId":"19"},{"holderEmpty":"1b","holderId":"20"},{"holderEmpty":"1b","holderId":"21"},{"holderEmpty":"1b","holderId":"22"},{"holderEmpty":"1b","holderId":"23"},{"holderEmpty":"1b","holderId":"24"},{"holderEmpty":"1b","holderId":"25"},{"holderEmpty":"1b","holderId":"26"},{"holderEmpty":"1b","holderId":"27"},{"holderEmpty":"1b","holderId":"28"},{"holderEmpty":"1b","holderId":"29"},{"holderEmpty":"1b","holderId":"30"},{"holderEmpty":"1b","holderId":"31"}],"outSlots":,"miscSlots":,"inSlots":,"sides":}},
            "elements": [
                "modularmachinery:blockoutputbus@6"
            ]
        },
        {
            "x": 0,
            "y": 0,
            "z": 2,
            "nbt": {"hatchSize":"7","casingColor":"16777215","id":"minecraft:tileenergyinputhatch","energy":"0L"},
            "elements": [
                "modularmachinery:blockenergyinputhatch@7"
            ]
        },
        {
            "x": 1,
            "y": 0,
            "z": 2,
            "elements": [
                "gregtechmod:block_advanced_machine_casing@0"
            ]
        },
        {
            "x": 1,
            "y": -1,
            "z": 0,
            "elements": [
                "gregtechmod:block_advanced_machine_casing@0"
            ]
        },
        {
            "x": 0,
            "y": -1,
            "z": 0,
            "elements": [
                "gregtechmod:block_advanced_machine_casing@0"
            ]
        },
        {
            "x": -1,
            "y": 1,
            "z": 0,
            "elements": [
                "gregtechmod:block_advanced_machine_casing@0"
            ]
        },
        {
            "x": -1,
            "y": -1,
            "z": 0,
            "elements": [
                "gregtechmod:block_advanced_machine_casing@0"
            ]
        },
        {
            "x": 0,
            "y": 1,
            "z": 0,
            "nbt": {"casingColor":"16777215","id":"minecraft:tilecolorablemachinecomponent"},
            "elements": [
                "modularmachinery:blockcasing@2"
            ]
        },
        {
            "x": -1,
            "y": 1,
            "z": 1,
            "nbt": {"input":"1b","size":"7","casingColor":"16777215","id":"minecraft:tilefluidinputhatch","tank":{"Empty":"","gasTag":{"Empty":""}}},
            "elements": [
                "modularmachinery:blockfluidinputhatch@7"
            ]
        },
        {
            "x": 1,
            "y": 1,
            "z": 0,
            "elements": [
                "gregtechmod:block_advanced_machine_casing@0"
            ]
        },
        {
            "x": -1,
            "y": 1,
            "z": 2,
            "elements": [
                "gregtechmod:block_advanced_machine_casing@0"
            ]
        },
        {
            "x": 0,
            "y": 1,
            "z": 2,
            "elements": [
                "gregtechmod:block_advanced_machine_casing@0"
            ]
        },
        {
            "x": 1,
            "y": 1,
            "z": 1,
            "nbt": {"input":"0b","size":"7","casingColor":"16777215","id":"minecraft:tilefluidoutputhatch","tank":{"Empty":"","gasTag":{"Empty":""}}},
            "elements": [
                "modularmachinery:blockfluidoutputhatch@7"
            ]
        },
        {
            "x": -1,
            "y": -1,
            "z": 1,
            "elements": [
                "gregtechmod:block_advanced_machine_casing@0"
            ]
        },
        {
            "x": 1,
            "y": 1,
            "z": 2,
            "elements": [
                "gregtechmod:block_advanced_machine_casing@0"
            ]
        },
        {
            "x": 0,
            "y": -1,
            "z": 1,
            "elements": [
                "gregtechmod:block_advanced_machine_casing@0"
            ]
        },
        {
            "x": -1,
            "y": -1,
            "z": 2,
            "elements": [
                "gregtechmod:block_advanced_machine_casing@0"
            ]
        },
        {
            "x": 0,
            "y": -1,
            "z": 2,
            "elements": [
                "gregtechmod:block_advanced_machine_casing@0"
            ]
        },
        {
            "x": 1,
            "y": -1,
            "z": 1,
            "elements": [
                "gregtechmod:block_advanced_machine_casing@0"
            ]
        },
        {
            "x": 1,
            "y": -1,
            "z": 2,
            "elements": [
                "gregtechmod:block_advanced_machine_casing@0"
            ]
        },
        {
            "x": -1,
            "y": 2,
            "z": 0,
            "elements": [
                "gregtechmod:block_advanced_machine_casing@0"
            ]
        },
        {
            "x": -1,
            "y": 2,
            "z": 1,
            "elements": [
                "gregtechmod:block_advanced_machine_casing@0"
            ]
        },
        {
            "x": 0,
            "y": 2,
            "z": 0,
            "elements": [
                "gregtechmod:block_advanced_machine_casing@0"
            ]
        },
        {
            "x": -1,
            "y": 2,
            "z": 2,
            "elements": [
                "gregtechmod:block_advanced_machine_casing@0"
            ]
        },
        {
            "x": 0,
            "y": 2,
            "z": 1,
            "elements": [
                "gregtechmod:block_advanced_machine_casing@0"
            ]
        },
        {
            "x": 1,
            "y": 2,
            "z": 0,
            "elements": [
                "gregtechmod:block_advanced_machine_casing@0"
            ]
        }
    ]}